Workbook

Sheet Summary
A1: SANVI AERO GARDENS
A2: Inventory Summary — every figure below is calculated from the Availability tab
A4: INVENTORY BY UNIT TYPE
A5: Unit Type | B5: Total Units | C5: Available | D5: Blocked | E5: Sold | F5: Total Area (Sq Ft) | G5: Available Area (Sq Ft)
A6: 1 BHK | B6: =COUNTIF(Availability!$D$8:$D$46,$A6) | C6: =COUNTIFS(Availability!$D$8:$D$46,$A6,Availability!$G$8:$G$46,"Available") | D6: =COUNTIFS(Availability!$D$8:$D$46,$A6,Availability!$G$8:$G$46,"Blocked") | E6: =COUNTIFS(Availability!$D$8:$D$46,$A6,Availability!$G$8:$G$46,"Sold") | F6: =SUMIF(Availability!$D$8:$D$46,$A6,Availability!$E$8:$E$46) | G6: =SUMIFS(Availability!$E$8:$E$46,Availability!$D$8:$D$46,$A6,Availability!$G$8:$G$46,"Available")
A7: 2 BHK | B7: =COUNTIF(Availability!$D$8:$D$46,$A7) | C7: =COUNTIFS(Availability!$D$8:$D$46,$A7,Availability!$G$8:$G$46,"Available") | D7: =COUNTIFS(Availability!$D$8:$D$46,$A7,Availability!$G$8:$G$46,"Blocked") | E7: =COUNTIFS(Availability!$D$8:$D$46,$A7,Availability!$G$8:$G$46,"Sold") | F7: =SUMIF(Availability!$D$8:$D$46,$A7,Availability!$E$8:$E$46) | G7: =SUMIFS(Availability!$E$8:$E$46,Availability!$D$8:$D$46,$A7,Availability!$G$8:$G$46,"Available")
A8: 3 BHK | B8: =COUNTIF(Availability!$D$8:$D$46,$A8) | C8: =COUNTIFS(Availability!$D$8:$D$46,$A8,Availability!$G$8:$G$46,"Available") | D8: =COUNTIFS(Availability!$D$8:$D$46,$A8,Availability!$G$8:$G$46,"Blocked") | E8: =COUNTIFS(Availability!$D$8:$D$46,$A8,Availability!$G$8:$G$46,"Sold") | F8: =SUMIF(Availability!$D$8:$D$46,$A8,Availability!$E$8:$E$46) | G8: =SUMIFS(Availability!$E$8:$E$46,Availability!$D$8:$D$46,$A8,Availability!$G$8:$G$46,"Available")
A9: TOTAL | B9: =SUM(B6:B8) | C9: =SUM(C6:C8) | D9: =SUM(D6:D8) | E9: =SUM(E6:E8) | F9: =SUM(F6:F8) | G9: =SUM(G6:G8)
A11: AVAILABLE UNITS BY FLOOR
A12: Floor | B12: Total Units | C12: Available | D12: Blocked | E12: Sold | F12: Available Area (Sq Ft)
A13: Ground | B13: =COUNTIF(Availability!$C$8:$C$46,$A13) | C13: =COUNTIFS(Availability!$C$8:$C$46,$A13,Availability!$G$8:$G$46,"Available") | D13: =COUNTIFS(Availability!$C$8:$C$46,$A13,Availability!$G$8:$G$46,"Blocked") | E13: =COUNTIFS(Availability!$C$8:$C$46,$A13,Availability!$G$8:$G$46,"Sold") | F13: =SUMIFS(Availability!$E$8:$E$46,Availability!$C$8:$C$46,$A13,Availability!$G$8:$G$46,"Available")
A14: 1 | B14: =COUNTIF(Availability!$C$8:$C$46,$A14) | C14: =COUNTIFS(Availability!$C$8:$C$46,$A14,Availability!$G$8:$G$46,"Available") | D14: =COUNTIFS(Availability!$C$8:$C$46,$A14,Availability!$G$8:$G$46,"Blocked") | E14: =COUNTIFS(Availability!$C$8:$C$46,$A14,Availability!$G$8:$G$46,"Sold") | F14: =SUMIFS(Availability!$E$8:$E$46,Availability!$C$8:$C$46,$A14,Availability!$G$8:$G$46,"Available")
A15: 2 | B15: =COUNTIF(Availability!$C$8:$C$46,$A15) | C15: =COUNTIFS(Availability!$C$8:$C$46,$A15,Availability!$G$8:$G$46,"Available") | D15: =COUNTIFS(Availability!$C$8:$C$46,$A15,Availability!$G$8:$G$46,"Blocked") | E15: =COUNTIFS(Availability!$C$8:$C$46,$A15,Availability!$G$8:$G$46,"Sold") | F15: =SUMIFS(Availability!$E$8:$E$46,Availability!$C$8:$C$46,$A15,Availability!$G$8:$G$46,"Available")
A16: 3 | B16: =COUNTIF(Availability!$C$8:$C$46,$A16) | C16: =COUNTIFS(Availability!$C$8:$C$46,$A16,Availability!$G$8:$G$46,"Available") | D16: =COUNTIFS(Availability!$C$8:$C$46,$A16,Availability!$G$8:$G$46,"Blocked") | E16: =COUNTIFS(Availability!$C$8:$C$46,$A16,Availability!$G$8:$G$46,"Sold") | F16: =SUMIFS(Availability!$E$8:$E$46,Availability!$C$8:$C$46,$A16,Availability!$G$8:$G$46,"Available")
A17: 4 | B17: =COUNTIF(Availability!$C$8:$C$46,$A17) | C17: =COUNTIFS(Availability!$C$8:$C$46,$A17,Availability!$G$8:$G$46,"Available") | D17: =COUNTIFS(Availability!$C$8:$C$46,$A17,Availability!$G$8:$G$46,"Blocked") | E17: =COUNTIFS(Availability!$C$8:$C$46,$A17,Availability!$G$8:$G$46,"Sold") | F17: =SUMIFS(Availability!$E$8:$E$46,Availability!$C$8:$C$46,$A17,Availability!$G$8:$G$46,"Available")
A18: 5 | B18: =COUNTIF(Availability!$C$8:$C$46,$A18) | C18: =COUNTIFS(Availability!$C$8:$C$46,$A18,Availability!$G$8:$G$46,"Available") | D18: =COUNTIFS(Availability!$C$8:$C$46,$A18,Availability!$G$8:$G$46,"Blocked") | E18: =COUNTIFS(Availability!$C$8:$C$46,$A18,Availability!$G$8:$G$46,"Sold") | F18: =SUMIFS(Availability!$E$8:$E$46,Availability!$C$8:$C$46,$A18,Availability!$G$8:$G$46,"Available")
A19: 6 | B19: =COUNTIF(Availability!$C$8:$C$46,$A19) | C19: =COUNTIFS(Availability!$C$8:$C$46,$A19,Availability!$G$8:$G$46,"Available") | D19: =COUNTIFS(Availability!$C$8:$C$46,$A19,Availability!$G$8:$G$46,"Blocked") | E19: =COUNTIFS(Availability!$C$8:$C$46,$A19,Availability!$G$8:$G$46,"Sold") | F19: =SUMIFS(Availability!$E$8:$E$46,Availability!$C$8:$C$46,$A19,Availability!$G$8:$G$46,"Available")
A21: SALEABLE VALUE
A22: Total saleable area (sq ft) | B22: =F9 | C22: Blue figures on yellow are the two inputs — change them here. Carried over from the original sheet; indicative only, the Cost Sheet governs pricing.
A23: Rate per sq ft (₹) | B23: 8000
A24: Gross saleable value (₹) | B24: =B22*B23
A25: Gross saleable value (₹ Cr) | B25: =B24/10000000
A26: Brokerage rate | B26: 0.035
A27: Brokerage value (₹) | B27: =B24*B26
A29: HOW TO USE THIS FILE
A30: Availability tab | B30: The working list. Use the drop-down in the Status column to set a unit to Available, Blocked or Sold.
A31: Filter | B31: Click the arrow on any header to show only what you need — e.g. Status = Available, Type = 2 BHK.
A32: Totals row | B32: The total at the bottom of the Availability tab counts only the rows the filter is showing.
A33: This tab | B33: Recalculates on its own. Nothing here needs to be typed except the two yellow cells above.

Sheet Availability
A1: SANVI AERO GARDENS
A2: Unit Availability | F2: Last updated: 07 Sep 2026
A4: TOTAL UNITS | C4: AVAILABLE | E4: BLOCKED | G4: SOLD
A5: =COUNTA($B$8:$B$46) | C5: =COUNTIF($G$8:$G$46,"Available") | E5: =COUNTIF($G$8:$G$46,"Blocked") | G5: =COUNTIF($G$8:$G$46,"Sold")
A7: S.No | B7: Unit No | C7: Floor | D7: Type | E7: Sale Area (Sq Ft) | F7: Facing | G7: Status | H7: Remarks
A8: =IF(B8="","",ROW()-7) | B8: 3 | C8: Ground | D8: 1 BHK | E8: 720 | F8: West Facing | G8: Available
A9: =IF(B9="","",ROW()-7) | B9: 19 | C9: Ground | D9: 1 BHK | E9: 625 | F9: North Facing | G9: Available
A10: =IF(B10="","",ROW()-7) | B10: 21 | C10: Ground | D10: 1 BHK | E10: 625 | F10: North Facing | G10: Available
A11: =IF(B11="","",ROW()-7) | B11: 126 | C11: 1 | D11: 1 BHK | E11: 625 | F11: North Facing | G11: Available
A12: =IF(B12="","",ROW()-7) | B12: 128 | C12: 1 | D12: 1 BHK | E12: 625 | F12: West Facing | G12: Available
A13: =IF(B13="","",ROW()-7) | B13: 132 | C13: 1 | D13: 1 BHK | E13: 625 | F13: West Facing | G13: Available
A14: =IF(B14="","",ROW()-7) | B14: 135 | C14: 1 | D14: 1 BHK | E14: 625 | F14: West Facing | G14: Available
A15: =IF(B15="","",ROW()-7) | B15: 203 | C15: 2 | D15: 1 BHK | E15: 790 | F15: West Facing | G15: Available
A16: =IF(B16="","",ROW()-7) | B16: 228 | C16: 2 | D16: 1 BHK | E16: 625 | F16: West Facing | G16: Available
A17: =IF(B17="","",ROW()-7) | B17: 232 | C17: 2 | D17: 1 BHK | E17: 625 | F17: West Facing | G17: Available
A18: =IF(B18="","",ROW()-7) | B18: 324 | C18: 3 | D18: 1 BHK | E18: 625 | F18: West Facing | G18: Available
A19: =IF(B19="","",ROW()-7) | B19: 328 | C19: 3 | D19: 1 BHK | E19: 625 | F19: West Facing | G19: Available
A20: =IF(B20="","",ROW()-7) | B20: 428 | C20: 4 | D20: 1 BHK | E20: 625 | F20: West Facing | G20: Available
A21: =IF(B21="","",ROW()-7) | B21: 524 | C21: 5 | D21: 1 BHK | E21: 625 | F21: West Facing | G21: Available
A22: =IF(B22="","",ROW()-7) | B22: 603 | C22: 6 | D22: 1 BHK | E22: 790 | F22: West Facing | G22: Available
A23: =IF(B23="","",ROW()-7) | B23: 7 | C23: Ground | D23: 2 BHK | E23: 925 | F23: East Facing | G23: Available
A24: =IF(B24="","",ROW()-7) | B24: 9 | C24: Ground | D24: 2 BHK | E24: 925 | F24: East Facing | G24: Available
A25: =IF(B25="","",ROW()-7) | B25: 12 | C25: Ground | D25: 2 BHK | E25: 925 | F25: East Facing | G25: Available
A26: =IF(B26="","",ROW()-7) | B26: 20 | C26: Ground | D26: 2 BHK | E26: 960 | F26: North Facing | G26: Available
A27: =IF(B27="","",ROW()-7) | B27: 120 | C27: 1 | D27: 2 BHK | E27: 1090 | F27: North Facing | G27: Available
A28: =IF(B28="","",ROW()-7) | B28: 131 | C28: 1 | D28: 2 BHK | E28: 955 | F28: West Facing | G28: Available
A29: =IF(B29="","",ROW()-7) | B29: 231 | C29: 2 | D29: 2 BHK | E29: 1075 | F29: West Facing | G29: Available
A30: =IF(B30="","",ROW()-7) | B30: 236 | C30: 2 | D30: 2 BHK | E30: 1100 | F30: North Facing | G30: Available
A31: =IF(B31="","",ROW()-7) | B31: 238 | C31: 2 | D31: 2 BHK | E31: 1055 | F31: West Facing | G31: Available
A32: =IF(B32="","",ROW()-7) | B32: 304 | C32: 3 | D32: 2 BHK | E32: 1040 | F32: East Facing | G32: Available
A33: =IF(B33="","",ROW()-7) | B33: 318 | C33: 3 | D33: 2 BHK | E33: 925 | F33: East Facing | G33: Available
A34: =IF(B34="","",ROW()-7) | B34: 401 | C34: 4 | D34: 2 BHK | E34: 900 | F34: South Facing | G34: Available
A35: =IF(B35="","",ROW()-7) | B35: 501 | C35: 5 | D35: 2 BHK | E35: 900 | F35: South Facing | G35: Available
A36: =IF(B36="","",ROW()-7) | B36: 614 | C36: 6 | D36: 2 BHK | E36: 925 | F36: East Facing | G36: Available
A37: =IF(B37="","",ROW()-7) | B37: 616 | C37: 6 | D37: 2 BHK | E37: 925 | F37: East Facing | G37: Available
A38: =IF(B38="","",ROW()-7) | B38: 618 | C38: 6 | D38: 2 BHK | E38: 925 | F38: East Facing | G38: Available
A39: =IF(B39="","",ROW()-7) | B39: 18 | C39: Ground | D39: 3 BHK | E39: 1265 | F39: East Facing | G39: Available
A40: =IF(B40="","",ROW()-7) | B40: 127 | C40: 1 | D40: 3 BHK | E40: 1265 | F40: East Facing | G40: Available
A41: =IF(B41="","",ROW()-7) | B41: 227 | C41: 2 | D41: 3 BHK | E41: 1265 | F41: East Facing | G41: Available
A42: =IF(B42="","",ROW()-7) | B42: 237 | C42: 2 | D42: 3 BHK | E42: 1395 | F42: West Facing | G42: Available
...
